Traceback (most recent call last):
  File "/Library/Frameworks/Python.framework/Versions/3.10/lib/python3.10/site-packages/jupyter_cache/executors/utils.py", line 58, in single_nb_execution
    executenb(
  File "/Users/belka/Library/Python/3.10/lib/python/site-packages/nbclient/client.py", line 1265, in execute
    return NotebookClient(nb=nb, resources=resources, km=km, **kwargs).execute()
  File "/Users/belka/Library/Python/3.10/lib/python/site-packages/jupyter_core/utils/__init__.py", line 166, in wrapped
    return loop.run_until_complete(inner)
  File "/Library/Frameworks/Python.framework/Versions/3.10/lib/python3.10/asyncio/base_events.py", line 646, in run_until_complete
    return future.result()
  File "/Users/belka/Library/Python/3.10/lib/python/site-packages/nbclient/client.py", line 703, in async_execute
    await self.async_execute_cell(
  File "/Users/belka/Library/Python/3.10/lib/python/site-packages/nbclient/client.py", line 1021, in async_execute_cell
    await self._check_raise_for_error(cell, cell_index, exec_reply)
  File "/Users/belka/Library/Python/3.10/lib/python/site-packages/nbclient/client.py", line 915, in _check_raise_for_error
    raise CellExecutionError.from_cell_and_msg(cell, exec_reply_content)
nbclient.exceptions.CellExecutionError: An error occurred while executing the following cell:
------------------
import geopandas as gpd

# Assuming theaters_gdf contains theater locations and okrug_gdf contains ATD polygons

# Perform spatial join to determine theaters in each ATD cell
theaters_in_atd = gpd.sjoin(theaters_gdf, okrug_gdf, op='within')

# Group by ATD cell and count theaters
theaters_count = theaters_in_atd.groupby('atd_id').size().reset_index(name='theater_count')

# Merge count information back to the original ATD GeoDataFrame
okrug_with_count = okrug_gdf.merge(theaters_count, on='atd_id', how='left')

# Save the updated GeoDataFrame to a new file
okrug_with_count.to_file('okrug_with_theater_count.shp')

------------------

[0;31m---------------------------------------------------------------------------[0m
[0;31mNameError[0m                                 Traceback (most recent call last)
Cell [0;32mIn[1], line 6[0m
[1;32m      1[0m [38;5;28;01mimport[39;00m [38;5;21;01mgeopandas[39;00m [38;5;28;01mas[39;00m [38;5;21;01mgpd[39;00m
[1;32m      3[0m [38;5;66;03m# Assuming theaters_gdf contains theater locations and okrug_gdf contains ATD polygons[39;00m
[1;32m      4[0m 
[1;32m      5[0m [38;5;66;03m# Perform spatial join to determine theaters in each ATD cell[39;00m
[0;32m----> 6[0m theaters_in_atd [38;5;241m=[39m gpd[38;5;241m.[39msjoin([43mtheaters_gdf[49m, okrug_gdf, op[38;5;241m=[39m[38;5;124m'[39m[38;5;124mwithin[39m[38;5;124m'[39m)
[1;32m      8[0m [38;5;66;03m# Group by ATD cell and count theaters[39;00m
[1;32m      9[0m theaters_count [38;5;241m=[39m theaters_in_atd[38;5;241m.[39mgroupby([38;5;124m'[39m[38;5;124matd_id[39m[38;5;124m'[39m)[38;5;241m.[39msize()[38;5;241m.[39mreset_index(name[38;5;241m=[39m[38;5;124m'[39m[38;5;124mtheater_count[39m[38;5;124m'[39m)

[0;31mNameError[0m: name 'theaters_gdf' is not defined
NameError: name 'theaters_gdf' is not defined

